<?xml version="1.0"?>
<!-- This URDF was automatically created by SolidWorks to URDF Exporter! Originally created by Stephen Brawner (brawner@gmail.com) 
     Commit Version: 1.6.0-4-g7f85cfe  Build Version: 1.6.7995.38578
     For more information, please see http://wiki.ros.org/sw_urdf_exporter -->
<robot
  name="Throwbot_urdf">
  <link
    name="base_link">
    <inertial>
      <origin
        xyz="-0.00194145275619461 -0.0182530975285205 -0.00489380208564417"
        rpy="0 0 0" />
      <mass
        value="1.30774880707658" />
      <inertia
        ixx="0.0104679258415776"
        ixy="1.2151111597938E-05"
        ixz="-0.000136884208294802"
        iyy="0.0126639768870947"
        iyz="2.48327849316574E-05"
        izz="0.00473617302136576" />
    </inertial>
    <visual>
      <origin
        xyz="0 0 0"
        rpy="0 0 0" />
      <geometry>
        <mesh
          filename="/home/vipul/ros2_ws/src/Throwbot_urdf/meshes/base_link.STL" />
      </geometry>
      <material
        name="">
        <color
          rgba="1 1 1 1" />
      </material>
    </visual>
    <collision>
      <origin
        xyz="0 0 0"
        rpy="0 0 0" />
      <geometry>
        <mesh
          filename="/home/vipul/ros2_ws/src/Throwbot_urdf/meshes/base_link.STL" />
      </geometry>
    </collision>
  </link>
  <link
    name="Wheel_left">
    <inertial>
      <origin
        xyz="8.2572837456496E-16 4.02455846426619E-16 -0.0150009270734002"
        rpy="0 0 0" />
      <mass
        value="0.207412192620305" />
      <inertia
        ixx="0.000587794710562155"
        ixy="-2.79001268702755E-14"
        ixz="-8.89231380829826E-19"
        iyy="0.000587794710290637"
        iyz="-1.41533698474194E-18"
        izz="0.00115682115581096" />
    </inertial>
    <visual>
      <origin
        xyz="0 0 0"
        rpy="0 0 0" />
      <geometry>
        <mesh
          filename="/home/vipul/ros2_ws/src/Throwbot_urdf/meshes/Wheel_left.STL" />
      </geometry>
      <material
        name="">
        <color
          rgba="0.796078431372549 0.823529411764706 0.937254901960784 1" />
      </material>
    </visual>
    <collision>
      <origin
        xyz="0 0 0"
        rpy="0 0 0" />
      <geometry>
        <mesh
          filename="/home/vipul/ros2_ws/src/Throwbot_urdf/meshes/Wheel_left.STL" />
      </geometry>
    </collision>
  </link>
  <joint
    name="left_wheel_system"
    type="continuous">
    <origin
      xyz="0.1305 0.1125 -0.008"
      rpy="-1.5708 -0.95739 1.5708" />
    <parent
      link="base_link" />
    <child
      link="Wheel_left" />
    <axis
      xyz="0 0 1" />
    <limit
      effort="50"
      velocity="5" />
  </joint>
  <link
    name="front_left">
    <inertial>
      <origin
        xyz="-4.16333634234434E-17 6.31439345255558E-16 0.0152048423837706"
        rpy="0 0 0" />
      <mass
        value="0.217125377961488" />
      <inertia
        ixx="0.000490311805364984"
        ixy="-1.77398785765337E-14"
        ixz="1.95560452690558E-19"
        iyy="0.000490297394860447"
        iyz="-1.14042098775052E-18"
        izz="0.000960245066104418" />
    </inertial>
    <visual>
      <origin
        xyz="0 0 0"
        rpy="0 0 0" />
      <geometry>
        <mesh
          filename="/home/vipul/ros2_ws/src/Throwbot_urdf/meshes/front_left.STL" />
      </geometry>
      <material
        name="">
        <color
          rgba="0.792156862745098 0.819607843137255 0.933333333333333 1" />
      </material>
    </visual>
    <collision>
      <origin
        xyz="0 0 0"
        rpy="0 0 0" />
      <geometry>
        <mesh
          filename="/home/vipul/ros2_ws/src/Throwbot_urdf/meshes/front_left.STL" />
      </geometry>
    </collision>
  </link>
  <joint
    name="front_left_wheel"
    type="continuous">
    <origin
      xyz="-0.12952 -0.18398 -0.030001"
      rpy="0 0 0.5601" />
    <parent
      link="Wheel_left" />
    <child
      link="front_left" />
    <axis
      xyz="0 0 0" />
    <limit
      effort="25"
      velocity="5" />
    <mimic
      joint="left_wheel_system"
      multiplier="1"
      offset="0" />
  </joint>
  <link
    name="wheel_right">
    <inertial>
      <origin
        xyz="6.24500451351651E-17 -2.70616862252382E-15 -0.0150009270734001"
        rpy="0 0 0" />
      <mass
        value="0.207412192620304" />
      <inertia
        ixx="0.000587794710562146"
        ixy="-2.82812984728036E-14"
        ixz="-4.82992205804824E-19"
        iyy="0.000587794710290077"
        iyz="-1.12791814190319E-18"
        izz="0.00115682115581039" />
    </inertial>
    <visual>
      <origin
        xyz="0 0 0"
        rpy="0 0 0" />
      <geometry>
        <mesh
          filename="/home/vipul/ros2_ws/src/Throwbot_urdf/meshes/wheel_right.STL" />
      </geometry>
      <material
        name="">
        <color
          rgba="0.796078431372549 0.823529411764706 0.937254901960784 1" />
      </material>
    </visual>
    <collision>
      <origin
        xyz="0 0 0"
        rpy="0 0 0" />
      <geometry>
        <mesh
          filename="/home/vipul/ros2_ws/src/Throwbot_urdf/meshes/wheel_right.STL" />
      </geometry>
    </collision>
  </link>
  <joint
    name="right_wheel"
    type="continuous">
    <origin
      xyz="-0.1305 0.1125 -0.008"
      rpy="-1.5708 -1.4974 -1.5708" />
    <parent
      link="base_link" />
    <child
      link="wheel_right" />
    <axis
      xyz="0 0 1" />
    <limit
      effort="50"
      velocity="5" />
  </joint>
  <link
    name="front_wheel_right">
    <inertial>
      <origin
        xyz="-9.71445146547012E-17 7.18175519054398E-16 0.0152048423837706"
        rpy="0 0 0" />
      <mass
        value="0.217125377961488" />
      <inertia
        ixx="0.000490311805365482"
        ixy="-1.75308579502056E-14"
        ixz="2.58996446532104E-19"
        iyy="0.000490297394859733"
        iyz="-1.68080163683409E-18"
        izz="0.000960245066104202" />
    </inertial>
    <visual>
      <origin
        xyz="0 0 0"
        rpy="0 0 0" />
      <geometry>
        <mesh
          filename="/home/vipul/ros2_ws/src/Throwbot_urdf/meshes/front_wheel_right.STL" />
      </geometry>
      <material
        name="">
        <color
          rgba="0.792156862745098 0.819607843137255 0.933333333333333 1" />
      </material>
    </visual>
    <collision>
      <origin
        xyz="0 0 0"
        rpy="0 0 0" />
      <geometry>
        <mesh
          filename="/home/vipul/ros2_ws/src/Throwbot_urdf/meshes/front_wheel_right.STL" />
      </geometry>
    </collision>
  </link>
  <joint
    name="right_wheel_front"
    type="continuous">
    <origin
      xyz="0.016489 0.22439 -0.030001"
      rpy="0 0 1.7974" />
    <parent
      link="wheel_right" />
    <child
      link="front_wheel_right" />
    <axis
      xyz="0 0 0" />
    <limit
      effort="25"
      velocity="5" />
    <mimic
      joint="right_wheel"
      multiplier="1"
      offset="0" />
  </joint>
  <link
    name="Arm">
    <inertial>
      <origin
        xyz="0.0748524433421241 -5.55111512312578E-16 1.07135582556292E-17"
        rpy="0 0 0" />
      <mass
        value="0.160244443747562" />
      <inertia
        ixx="0.000115768775605391"
        ixy="-6.09863722023096E-20"
        ixz="-5.39145143616527E-19"
        iyy="0.00121442026810451"
        iyz="-1.48079135617434E-10"
        izz="0.00132805582485749" />
    </inertial>
    <visual>
      <origin
        xyz="0 0 0"
        rpy="0 0 0" />
      <geometry>
        <mesh
          filename="/home/vipul/ros2_ws/src/Throwbot_urdf/meshes/Arm.STL" />
      </geometry>
      <material
        name="">
        <color
          rgba="0.972549019607843 0.945098039215686 0.780392156862745 1" />
      </material>
    </visual>
    <collision>
      <origin
        xyz="0 0 0"
        rpy="0 0 0" />
      <geometry>
        <mesh
          filename="/home/vipul/ros2_ws/src/Throwbot_urdf/meshes/Arm.STL" />
      </geometry>
    </collision>
  </link>
  <joint
    name="arm"
    type="continuous">
    <origin
      xyz="0 -0.1125 -0.008"
      rpy="1.5708 -0.78598 -1.5708" />
    <parent
      link="base_link" />
    <child
      link="Arm" />
    <axis
      xyz="0 0 1" />
    <limit
      lower="0"
      upper="3.14"
      effort="10"
      velocity="2" />
  </joint>
  <link
    name="cam_rear">
    <inertial>
      <origin
        xyz="3.98694163187656E-05 -2.18994418986346E-05 0.00960724219329304"
        rpy="0 0 0" />
      <mass
        value="0.026441694751393" />
      <inertia
        ixx="4.48821247529358E-06"
        ixy="-2.30867187434244E-11"
        ixz="-1.14833079764263E-08"
        iyy="4.12805875452281E-06"
        iyz="-2.08880374103012E-09"
        izz="5.76402911005741E-06" />
    </inertial>
    <visual>
      <origin
        xyz="0 0 0"
        rpy="0 0 0" />
      <geometry>
        <mesh
          filename="/home/vipul/ros2_ws/src/Throwbot_urdf/meshes/cam_rear.STL" />
      </geometry>
      <material
        name="">
        <color
          rgba="0.792156862745098 0.819607843137255 0.933333333333333 1" />
      </material>
    </visual>
    <collision>
      <origin
        xyz="0 0 0"
        rpy="0 0 0" />
      <geometry>
        <mesh
          filename="/home/vipul/ros2_ws/src/Throwbot_urdf/meshes/cam_rear.STL" />
      </geometry>
    </collision>
  </link>
  <joint
    name="rear_cam"
    type="fixed">
    <origin
      xyz="-0.02 0.135 0.018"
      rpy="1.5708 0 3.1416" />
    <parent
      link="base_link" />
    <child
      link="cam_rear" />
    <axis
      xyz="0 0 0" />
  </joint>
  <link
    name="cam_left">
    <inertial>
      <origin
        xyz="3.9869416318768E-05 -2.18994418986372E-05 0.00960724219329306"
        rpy="0 0 0" />
      <mass
        value="0.026441694751393" />
      <inertia
        ixx="4.48821247529358E-06"
        ixy="-2.30867187441037E-11"
        ixz="-1.14833079764265E-08"
        iyy="4.12805875452281E-06"
        iyz="-2.08880374103061E-09"
        izz="5.76402911005741E-06" />
    </inertial>
    <visual>
      <origin
        xyz="0 0 0"
        rpy="0 0 0" />
      <geometry>
        <mesh
          filename="/home/vipul/ros2_ws/src/Throwbot_urdf/meshes/cam_left.STL" />
      </geometry>
      <material
        name="">
        <color
          rgba="0.792156862745098 0.819607843137255 0.933333333333333 1" />
      </material>
    </visual>
    <collision>
      <origin
        xyz="0 0 0"
        rpy="0 0 0" />
      <geometry>
        <mesh
          filename="/home/vipul/ros2_ws/src/Throwbot_urdf/meshes/cam_left.STL" />
      </geometry>
    </collision>
  </link>
  <joint
    name="left_cam"
    type="fixed">
    <origin
      xyz="0.096 0 -0.005"
      rpy="1.5708 0 1.5708" />
    <parent
      link="base_link" />
    <child
      link="cam_left" />
    <axis
      xyz="0 0 0" />
  </joint>
  <link
    name="cam_right">
    <inertial>
      <origin
        xyz="3.98694159912305E-05 -2.18994424927383E-05 0.00960724219329304"
        rpy="0 0 0" />
      <mass
        value="0.026441694751393" />
      <inertia
        ixx="4.48821247529288E-06"
        ixy="-2.30920854525675E-11"
        ixz="-1.14833080073286E-08"
        iyy="4.12805875452349E-06"
        iyz="-2.08880356991558E-09"
        izz="5.7640291100574E-06" />
    </inertial>
    <visual>
      <origin
        xyz="0 0 0"
        rpy="0 0 0" />
      <geometry>
        <mesh
          filename="/home/vipul/ros2_ws/src/Throwbot_urdf/meshes/cam_right.STL" />
      </geometry>
      <material
        name="">
        <color
          rgba="0.792156862745098 0.819607843137255 0.933333333333333 1" />
      </material>
    </visual>
    <collision>
      <origin
        xyz="0 0 0"
        rpy="0 0 0" />
      <geometry>
        <mesh
          filename="/home/vipul/ros2_ws/src/Throwbot_urdf/meshes/cam_right.STL" />
      </geometry>
    </collision>
  </link>
  <joint
    name="right_cam"
    type="fixed">
    <origin
      xyz="-0.096 0 -0.005"
      rpy="1.5708 0 -1.5708" />
    <parent
      link="base_link" />
    <child
      link="cam_right" />
    <axis
      xyz="0 0 0" />
  </joint>
  <link
    name="cam_front">
    <inertial>
      <origin
        xyz="-0.0109601305836812 -0.00152189944189864 0.00760724219329309"
        rpy="0 0 0" />
      <mass
        value="0.026441694751393" />
      <inertia
        ixx="4.48821247529358E-06"
        ixy="-2.30867187429472E-11"
        ixz="-1.14833079764258E-08"
        iyy="4.12805875452281E-06"
        iyz="-2.08880374103213E-09"
        izz="5.76402911005741E-06" />
    </inertial>
    <visual>
      <origin
        xyz="0 0 0"
        rpy="0 0 0" />
      <geometry>
        <mesh
          filename="/home/vipul/ros2_ws/src/Throwbot_urdf/meshes/cam_front.STL" />
      </geometry>
      <material
        name="">
        <color
          rgba="0.792156862745098 0.819607843137255 0.933333333333333 1" />
      </material>
    </visual>
    <collision>
      <origin
        xyz="0 0 0"
        rpy="0 0 0" />
      <geometry>
        <mesh
          filename="/home/vipul/ros2_ws/src/Throwbot_urdf/meshes/cam_front.STL" />
      </geometry>
    </collision>
  </link>
  <joint
    name="front_cam"
    type="continuous">
    <origin
      xyz="0 -0.1325 0.01"
      rpy="-1.6291 0 -3.1416" />
    <parent
      link="base_link" />
    <child
      link="cam_front" />
    <axis
      xyz="1 0 0" />
  </joint>
</robot>